<?xml version="1.0" encoding="utf-8"?>
<robot name="iiwa">
  <link name="world"/>
  <link name="lbr_iiwa_link_1">
    <inertial>
      <origin xyz="0.0 -0.03 0.12" rpy="0.0 0.0 0.0"/>
      <mass value="4.0"/>
      <inertia ixx="0.1" ixy="0.0" ixz="0.0" iyy="0.09000000000000001" iyz="0.0" izz="0.02"/>
    </inertial>
  </link>
  <link name="lbr_iiwa_link_2">
    <inertial>
      <origin xyz="0.0003 0.059 0.042" rpy="0.0 0.0 0.0"/>
      <mass value="4.0"/>
      <inertia ixx="0.05" ixy="0.0" ixz="0.0" iyy="0.018" iyz="0.0" izz="0.044"/>
    </inertial>
  </link>
  <link name="lbr_iiwa_link_3">
    <inertial>
      <origin xyz="0.0 0.03 0.13" rpy="0.0 0.0 0.0"/>
      <mass value="3.0"/>
      <inertia ixx="0.08000000000000002" ixy="0.0" ixz="0.0" iyy="0.07500000000000001" iyz="0.0" izz="0.01"/>
    </inertial>
  </link>
  <link name="lbr_iiwa_link_4">
    <inertial>
      <origin xyz="0.0 0.067 0.034" rpy="0.0 0.0 0.0"/>
      <mass value="2.7"/>
      <inertia ixx="0.03" ixy="0.0" ixz="0.0" iyy="0.009999999999999998" iyz="0.0" izz="0.029"/>
    </inertial>
  </link>
  <link name="lbr_iiwa_link_5">
    <inertial>
      <origin xyz="0.0001 0.021 0.07599999999999998" rpy="0.0 0.0 0.0"/>
      <mass value="1.7"/>
      <inertia ixx="0.019999999999999997" ixy="0.0" ixz="0.0" iyy="0.018" iyz="0.0" izz="0.005"/>
    </inertial>
  </link>
  <link name="lbr_iiwa_link_6">
    <inertial>
      <origin xyz="0.0 0.0006 0.0004" rpy="0.0 0.0 0.0"/>
      <mass value="1.8"/>
      <inertia ixx="0.005" ixy="0.0" ixz="0.0" iyy="0.0036" iyz="0.0" izz="0.0047"/>
    </inertial>
  </link>
  <link name="lbr_iiwa_link_7">
    <inertial>
      <origin xyz="0.0 0.0 0.02" rpy="0.0 0.0 0.0"/>
      <mass value="0.3"/>
      <inertia ixx="0.001" ixy="0.0" ixz="0.0" iyy="0.001" iyz="0.0" izz="0.001"/>
    </inertial>
  </link>
  <joint name="lbr_iiwa_joint_1" type="revolute">
    <parent link="world"/>
    <child link="lbr_iiwa_link_1"/>
    <origin xyz="0.0 0.0 0.1575" rpy="0.0 -0.0 0.0"/>
    <axis xyz="0.0 0.0 1.0"/>
    <limit lower="-2.96705972839" upper="2.96705972839" effort="300.0" velocity="10.0"/>
  </joint>
  <joint name="lbr_iiwa_joint_2" type="revolute">
    <parent link="lbr_iiwa_link_1"/>
    <child link="lbr_iiwa_link_2"/>
    <origin xyz="0.0 0.0 0.2025" rpy="1.57079632679 0.0 -3.1415926535895866"/>
    <axis xyz="0.0 0.0 1.0"/>
    <limit lower="-2.09439510239" upper="2.09439510239" effort="300.0" velocity="10.0"/>
  </joint>
  <joint name="lbr_iiwa_joint_3" type="revolute">
    <parent link="lbr_iiwa_link_2"/>
    <child link="lbr_iiwa_link_3"/>
    <origin xyz="0.0 0.2045 0.0" rpy="1.57079632679 0.0 -3.1415926535895866"/>
    <axis xyz="0.0 0.0 1.0"/>
    <limit lower="-2.96705972839" upper="2.96705972839" effort="300.0" velocity="10.0"/>
  </joint>
  <joint name="lbr_iiwa_joint_4" type="revolute">
    <parent link="lbr_iiwa_link_3"/>
    <child link="lbr_iiwa_link_4"/>
    <origin xyz="0.0 0.0 0.2155" rpy="1.57079632679 0.0 0.0"/>
    <axis xyz="0.0 0.0 1.0"/>
    <limit lower="-2.09439510239" upper="2.09439510239" effort="300.0" velocity="10.0"/>
  </joint>
  <joint name="lbr_iiwa_joint_5" type="revolute">
    <parent link="lbr_iiwa_link_4"/>
    <child link="lbr_iiwa_link_5"/>
    <origin xyz="0.0 0.1845 0.0" rpy="1.5707963267997933 -2.0682310711021444e-13 -3.141592653589793"/>
    <axis xyz="0.0 0.0 1.0"/>
    <limit lower="-2.96705972839" upper="2.96705972839" effort="300.0" velocity="10.0"/>
  </joint>
  <joint name="lbr_iiwa_joint_6" type="revolute">
    <parent link="lbr_iiwa_link_5"/>
    <child link="lbr_iiwa_link_6"/>
    <origin xyz="0.0 0.0 0.2155" rpy="1.57079632679 0.0 0.0"/>
    <axis xyz="0.0 0.0 1.0"/>
    <limit lower="-2.09439510239" upper="2.09439510239" effort="300.0" velocity="10.0"/>
  </joint>
  <joint name="lbr_iiwa_joint_7" type="revolute">
    <parent link="lbr_iiwa_link_6"/>
    <child link="lbr_iiwa_link_7"/>
    <origin xyz="0.0 0.081 0.0" rpy="1.5707963267997933 -2.0682310711021444e-13 -3.141592653589793"/>
    <axis xyz="0.0 0.0 1.0"/>
    <limit lower="-3.05432619099" upper="3.05432619099" effort="300.0" velocity="10.0"/>
  </joint>
</robot>
